<?xml version="1.0"?>
<sdf version='1.6'>
	<model name='youbot'>
		
		<!-- In order to move the youbot without use wheels-->
		<link name="world" >
			<!-- <pose>0 0 0.1 0 0 0</pose> -->
		</link>

		<link name="virtual_link_xy" />

		<joint name="virtual_joint_x" type="prismatic">
			<axis>
				<xyz>1 0 0</xyz>
				<limit>
					<lower>-5</lower>
					<upper>5</upper>
					<effort>1</effort>
					<velocity>1</velocity>
				</limit>
			</axis>

			<parent>world</parent>
			<child>virtual_link_xy</child>
			
		</joint>

		<link name="virtual_link_yz" />

		<joint name="virtual_joint_y" type="prismatic">
			<axis>
				<xyz>0 1 0</xyz>
				<limit>
					<lower>-5</lower>
					<upper>5</upper>
					<effort>1</effort>
					<velocity>1</velocity>
				</limit>
			</axis>
			<parent>virtual_link_xy</parent>
			<child>virtual_link_yz</child>
		</joint>

		<joint name="virtual_joint_z" type="revolute">
			<axis>
				<xyz>0 0 1</xyz>
				<limit>
					<lower>-128</lower>
					<upper>128</upper>
					<effort>1</effort>
					<velocity>1</velocity>
				</limit>
			</axis>
			<parent>virtual_link_yz</parent>
			<child>base_footprint</child>
		</joint>

		
		<link name='base_footprint'>
			<pose frame=''>0 0 0 0 0 0</pose>
			<inertial>
				<pose frame=''>0.000408 0 0.003114 0 -0 0</pose>
				<mass>24.105</mass>
				<inertia>
					<ixx>6.7763</ixx>
					<ixy>-0.00971993</ixy>
					<ixz>1.29721</ixz>
					<iyy>6.85049</iyy>
					<iyz>-0.00737958</iyz>
					<izz>4.86015</izz>
				</inertia>
			</inertial>
			<collision name='base_footprint_collision'>
				<pose frame=''>0 0 -0.05 0 -0 0</pose>
				<geometry>
					<box>
						<size>0.001 0.001 0.001</size>
					</box>
				</geometry>
				<max_contacts>10</max_contacts>
				<surface>
					<contact>
						<ode/>
					</contact>
					<bounce/>
					<friction>
						<torsional>
							<ode/>
						</torsional>
						<ode/>
					</friction>
				</surface>
			</collision>
			<collision name='base_footprint_fixed_joint_lump__base_link_collision_1'>
				<pose frame=''>0 0 0 0 -0 0</pose>
				<geometry>
					<mesh>
						<scale>1 1 1</scale>
						<uri>model://youbot/meshes/youbot_base/base_convex.dae</uri>
					</mesh>
				</geometry>
				<max_contacts>10</max_contacts>
				<surface>
					<contact>
						<ode/>
					</contact>
					<bounce/>
					<friction>
						<torsional>
							<ode/>
						</torsional>
						<ode/>
					</friction>
				</surface>
			</collision>
			<collision name='base_footprint_fixed_joint_lump__arm_link_0_collision_2'>
				<pose frame=''>0.143 0 0.046 0 -0 0</pose>
				<geometry>
					<mesh>
						<scale>1 1 1</scale>
						<uri>model://youbot/meshes/youbot_arm/arm0_convex.dae</uri>
					</mesh>
				</geometry>
				<surface>
					<contact>
						<ode/>
					</contact>
					<friction>
						<ode/>
						<torsional>
							<ode/>
						</torsional>
					</friction>
					<bounce/>
				</surface>
				<max_contacts>10</max_contacts>
			</collision>
			<collision name='base_footprint_fixed_joint_lump__base_laser_front_link_collision_3'>
				<pose frame=''>0.3 0 -0.03 0 -0 0</pose>
				<geometry>
					<mesh>
						<scale>1 1 1</scale>
						<uri>model://youbot/meshes/sensors/hokuyo_convex.dae</uri>
					</mesh>
				</geometry>
				<surface>
					<contact>
						<ode/>
					</contact>
					<friction>
						<ode/>
						<torsional>
							<ode/>
						</torsional>
					</friction>
					<bounce/>
				</surface>
				<max_contacts>10</max_contacts>
			</collision>
			<collision name='base_footprint_fixed_joint_lump__plate_link_collision_4'>
				<pose frame=''>-0.159 0 0.046 0 -0 0</pose>
				<geometry>
					<mesh>
						<scale>1 1 1</scale>
						<uri>model://youbot/meshes/youbot_plate/plate_convex.dae</uri>
					</mesh>
				</geometry>
				<max_contacts>10</max_contacts>
				<surface>
					<contact>
						<ode/>
					</contact>
					<bounce/>
					<friction>
						<torsional>
							<ode/>
						</torsional>
						<ode/>
					</friction>
				</surface>
			</collision>
			<visual name='base_footprint_visual'>
				<pose frame=''>0 0 0 0 -0 0</pose>
				<geometry>
					<box>
						<size>0.001 0.001 0.001</size>
					</box>
				</geometry>
			</visual>
			<visual name='base_footprint_fixed_joint_lump__base_link_visual_1'>
				<pose frame=''>0 0 0 0 -0 0</pose>
				<geometry>
					<mesh>
						<scale>1 1 1</scale>
						<uri>model://youbot/meshes/youbot_base/base.dae</uri>
					</mesh>
				</geometry>
			</visual>
			<visual name='base_footprint_fixed_joint_lump__arm_link_0_visual_2'>
				<pose frame=''>0.143 0 0.046 0 -0 0</pose>
				<geometry>
					<mesh>
						<scale>1 1 1</scale>
						<uri>model://youbot/meshes/youbot_arm/arm0.dae</uri>
					</mesh>
				</geometry>
				<material>
					<script>
						<name>youbot/DarkGrey</name>
						<uri>model://youbot/materials/gazebo.material</uri>
					</script>
				</material>
			</visual>
			<visual name='base_footprint_fixed_joint_lump__base_laser_front_link_visual_3'>
				<pose frame=''>0.3 0 -0.03 0 -0 0</pose>
				<geometry>
					<mesh>
						<scale>1 1 1</scale>
						<uri>model://youbot/meshes/sensors/hokuyo.dae</uri>
					</mesh>
				</geometry>
				<material>
					<!--<script>
							<uri>__default__</uri>
							<name>__default__</name>
						</script>--></material>
			</visual>
			<visual name='base_footprint_fixed_joint_lump__plate_link_visual_4'>
				<pose frame=''>-0.159 0 0.046 0 -0 0</pose>
				<geometry>
					<mesh>
						<scale>1 1 1</scale>
						<uri>model://youbot/meshes/youbot_plate/plate.dae</uri>
					</mesh>
				</geometry>
			</visual>
			<velocity_decay/>
			<gravity>1</gravity>
			<velocity_decay/>
			<self_collide>0</self_collide>
			<sensor name='base_laser_front'
			        type='gpu_ray'>
				<always_on>1</always_on>
				<update_rate>10</update_rate>
				<visualize>0</visualize>
				<ray>
					<scan>
						<horizontal>
							<samples>150</samples>
							<resolution>1</resolution>
							<min_angle>-1.57</min_angle>
							<max_angle>1.57</max_angle>
						</horizontal>
						<vertical>
							<samples>1</samples>
							<min_angle>0</min_angle>
							<max_angle>0</max_angle>
						</vertical>
					</scan>
					<range>
						<min>0.05</min>
						<max>5.6</max>
						<resolution>0.36</resolution>
					</range>
					<noise>
						<type>gaussian</type>
						<mean>0.00</mean>
						<stddev>0.01</stddev>
					</noise>
				</ray>
				<update_rate>10</update_rate>
				<plugin name='gazebo_ros_base_laser_front_controller'
				        filename='libgazebo_ros_ray_sensor.so'>
					<ros>
						<namespace>/youbot</namespace>
						<argument>--ros-args --remap ~/out:=scan</argument>
					</ros>
					<output_type>sensor_msgs/LaserScan</output_type>
				</plugin>
				<pose frame=''>0.3 0 -0.03 0 -0 0</pose>
			</sensor>
			<kinematic>0</kinematic>
		</link>
		<link name='arm_link_1'>
			<pose frame=''>0.167 0 0.142 0 -0 2.96706</pose>
			<inertial>
				<pose frame=''>0.01489 0.00213 0.00213 0 -0 0</pose>
				<mass>2.412</mass>
				<inertia>
					<ixx>0.003863</ixx>
					<ixy>-0.000979</ixy>
					<ixz>0</ixz>
					<iyy>0.006196</iyy>
					<iyz>0</iyz>
					<izz>0.006369</izz>
				</inertia>
			</inertial>
			<collision name='arm_link_1_collision'>
				<pose frame=''>0 0 0 0 -0 0</pose>
				<geometry>
					<mesh>
						<scale>1 1 1</scale>
						<uri>model://youbot/meshes/youbot_arm/arm1_convex.dae</uri>
					</mesh>
				</geometry>
				<surface>
					<contact>
						<ode/>
					</contact>
					<friction>
						<ode/>
						<torsional>
							<ode/>
						</torsional>
					</friction>
					<bounce/>
				</surface>
				<max_contacts>10</max_contacts>
			</collision>
			<visual name='arm_link_1_visual'>
				<pose frame=''>0 0 0 0 -0 0</pose>
				<geometry>
					<mesh>
						<scale>1 1 1</scale>
						<uri>model://youbot/meshes/youbot_arm/arm1.dae</uri>
					</mesh>
				</geometry>
				<material>
					<!--<script>
							<uri>__default__</uri>
							<name>__default__</name>
						</script>--></material>
			</visual>
			<gravity>1</gravity>
			<velocity_decay/>
			<self_collide>0</self_collide>
			<kinematic>0</kinematic>
		</link>
		<joint name='arm_joint_1'
		       type='revolute'>
			<child>arm_link_1</child>
			<parent>base_footprint</parent>
			<axis>
				<xyz>0 0 -1</xyz>
				<limit>
					<lower>0</lower>
					<upper>5.89921</upper>
					<effort>9.5</effort>
					<velocity>1.5708</velocity>
				</limit>
				<dynamics>
					<damping>1</damping>
					<friction>1</friction>
					<spring_reference>0</spring_reference>
					<spring_stiffness>0</spring_stiffness>
				</dynamics>
				<use_parent_model_frame>1</use_parent_model_frame>
			</axis>
		</joint>
		<link name='arm_link_2'>
			<pose frame=''>0.134501 0.00573 0.161 0 -1.13446 2.96706</pose>
			<inertial>
				<pose frame=''>0.10453 0.0017 -0.00297 0 -0 0</pose>
				<mass>1.155</mass>
				<inertia>
					<ixx>0.000823</ixx>
					<ixy>0</ixy>
					<ixz>-0</ixz>
					<iyy>0.004447</iyy>
					<iyz>0</iyz>
					<izz>0.004439</izz>
				</inertia>
			</inertial>
			<collision name='arm_link_2_collision'>
				<pose frame=''>0 -0.032 0.078 0 -0 0</pose>
				<geometry>
					<mesh>
						<scale>1 1 1</scale>
						<uri>model://youbot/meshes/youbot_arm/arm2_convex.dae</uri>
					</mesh>
				</geometry>
				<surface>
					<contact>
						<ode/>
					</contact>
					<friction>
						<ode/>
						<torsional>
							<ode/>
						</torsional>
					</friction>
					<bounce/>
				</surface>
				<max_contacts>10</max_contacts>
			</collision>
			<visual name='arm_link_2_visual'>
				<pose frame=''>0 -0.032 0.078 0 -0 0</pose>
				<geometry>
					<mesh>
						<scale>1 1 1</scale>
						<uri>model://youbot/meshes/youbot_arm/arm2.dae</uri>
					</mesh>
				</geometry>
				<material>
					<!--<script>
							<uri>__default__</uri>
							<name>__default__</name>
						</script>--></material>
			</visual>
			<gravity>1</gravity>
			<velocity_decay/>
			<self_collide>0</self_collide>
			<kinematic>0</kinematic>
		</link>
		<joint name='arm_joint_2'
		       type='revolute'>
			<child>arm_link_2</child>
			<parent>arm_link_1</parent>
			<axis>
				<xyz>-0.173648 -0.984808 0</xyz>
				<limit>
					<lower>0</lower>
					<upper>2.70526</upper>
					<effort>9.5</effort>
					<velocity>1.5708</velocity>
				</limit>
				<dynamics>
					<damping>1</damping>
					<friction>1</friction>
					<spring_reference>0</spring_reference>
					<spring_stiffness>0</spring_stiffness>
				</dynamics>
				<use_parent_model_frame>1</use_parent_model_frame>
			</axis>
		</joint>
		<link name='arm_link_3'>
			<pose frame=''>0.272845 -0.018663 0.226506 -0 1.41372 2.96706</pose>
			<inertial>
				<pose frame=''>0.0001 0.0967 0.02107 0 -0 0</pose>
				<mass>0.934</mass>
				<inertia>
					<ixx>0.002459</ixx>
					<ixy>0</ixy>
					<ixz>0</ixz>
					<iyy>0.002571</iyy>
					<iyz>-0</iyz>
					<izz>0.000535</izz>
				</inertia>
			</inertial>
			<collision name='arm_link_3_collision'>
				<pose frame=''>0 0.028 0.079 0 -0 0</pose>
				<geometry>
					<mesh>
						<scale>1 1 1</scale>
						<uri>model://youbot/meshes/youbot_arm/arm3_convex.dae</uri>
					</mesh>
				</geometry>
				<surface>
					<contact>
						<ode/>
					</contact>
					<friction>
						<ode/>
						<torsional>
							<ode/>
						</torsional>
					</friction>
					<bounce/>
				</surface>
				<max_contacts>10</max_contacts>
			</collision>
			<visual name='arm_link_3_visual'>
				<pose frame=''>0 0.028 0.079 0 -0 0</pose>
				<geometry>
					<mesh>
						<scale>1 1 1</scale>
						<uri>model://youbot/meshes/youbot_arm/arm3.dae</uri>
					</mesh>
				</geometry>
				<material>
					<!--<script>
							<uri>__default__</uri>
							<name>__default__</name>
						</script>--></material>
			</visual>
			<gravity>1</gravity>
			<velocity_decay/>
			<self_collide>0</self_collide>
			<kinematic>0</kinematic>
		</link>
		<joint name='arm_joint_3'
		       type='revolute'>
			<child>arm_link_3</child>
			<parent>arm_link_2</parent>
			<axis>
				<xyz>-0.173648 -0.984808 0</xyz>
				<limit>
					<lower>-5.18363</lower>
					<upper>0</upper>
					<effort>6</effort>
					<velocity>1.5708</velocity>
				</limit>
				<dynamics>
					<damping>1</damping>
					<friction>1</friction>
					<spring_reference>0</spring_reference>
					<spring_stiffness>0</spring_stiffness>
				</dynamics>
				<use_parent_model_frame>1</use_parent_model_frame>
			</axis>
		</joint>
		<link name='arm_link_4'>
			<pose frame=''>0.141533 0.004491 0.247624 0 -0.375246 2.96706</pose>
			<inertial>
				<pose frame=''>0.00011 0.05103 -0.02319 0 -0 0</pose>
				<mass>0.877</mass>
				<inertia>
					<ixx>0.000869</ixx>
					<ixy>0</ixy>
					<ixz>-0</ixz>
					<iyy>0.001173</iyy>
					<iyz>-0.000231</iyz>
					<izz>0.001091</izz>
				</inertia>
			</inertial>
			<collision name='arm_link_4_collision'>
				<pose frame=''>0 -0.01 0.029 0 -0 0</pose>
				<geometry>
					<mesh>
						<scale>1 1 1</scale>
						<uri>model://youbot/meshes/youbot_arm/arm4_convex.dae</uri>
					</mesh>
				</geometry>
				<surface>
					<contact>
						<ode/>
					</contact>
					<friction>
						<ode/>
						<torsional>
							<ode/>
						</torsional>
					</friction>
					<bounce/>
				</surface>
				<max_contacts>10</max_contacts>
			</collision>
			<visual name='arm_link_4_visual'>
				<pose frame=''>0 -0.01 0.029 0 -0 0</pose>
				<geometry>
					<mesh>
						<scale>1 1 1</scale>
						<uri>model://youbot/meshes/youbot_arm/arm4.dae</uri>
					</mesh>
				</geometry>
				<material>
					<!--<script>
							<uri>__default__</uri>
							<name>__default__</name>
						</script>--></material>
			</visual>
			<gravity>1</gravity>
			<velocity_decay/>
			<self_collide>0</self_collide>
			<kinematic>0</kinematic>
		</link>
		<joint name='arm_joint_4'
		       type='revolute'>
			<child>arm_link_4</child>
			<parent>arm_link_3</parent>
			<axis>
				<xyz>-0.173648 -0.984808 0</xyz>
				<limit>
					<lower>0</lower>
					<upper>3.57792</upper>
					<effort>2</effort>
					<velocity>1.5708</velocity>
				</limit>
				<dynamics>
					<damping>1</damping>
					<friction>1</friction>
					<spring_reference>0</spring_reference>
					<spring_stiffness>0</spring_stiffness>
				</dynamics>
				<use_parent_model_frame>1</use_parent_model_frame>
			</axis>
		</joint>
		<link name='arm_link_5'>
			<pose frame=''>0.190287 -0.004106 0.367846 -0.085052 0.365926 -0.408446</pose>
			<inertial>
				<pose frame=''>0 0.000822 -0.012035 0 -0 0</pose>
				<mass>0.351</mass>
				<inertia>
					<ixx>0.0103003</ixx>
					<ixy>0</ixy>
					<ixz>0</ixz>
					<iyy>0.0103593</iyy>
					<iyz>1.38404e-06</iyz>
					<izz>0.0101191</izz>
				</inertia>
			</inertial>
			<collision name='arm_link_5_collision'>
				<pose frame=''>0.003 0 -0.034 0 -0 0</pose>
				<geometry>
					<mesh>
						<scale>1 1 1</scale>
						<uri>model://youbot/meshes/youbot_arm/arm5_convex.dae</uri>
					</mesh>
				</geometry>
				<surface>
					<contact>
						<ode/>
					</contact>
					<friction>
						<ode/>
						<torsional>
							<ode/>
						</torsional>
					</friction>
					<bounce/>
				</surface>
				<max_contacts>10</max_contacts>
			</collision>
			<collision name='arm_link_5_fixed_joint_lump__gripper_palm_link_collision_1'>
				<pose frame=''>0 0 0 0 -0 0</pose>
				<geometry>
					<mesh>
						<scale>1 1 1</scale>
						<uri>model://youbot/meshes/youbot_gripper/palm_convex.dae</uri>
					</mesh>
				</geometry>
				<surface>
					<contact>
						<ode/>
					</contact>
					<friction>
						<ode/>
						<torsional>
							<ode/>
						</torsional>
					</friction>
					<bounce/>
				</surface>
				<max_contacts>10</max_contacts>
			</collision>
			<visual name='arm_link_5_visual'>
				<pose frame=''>0.003 0 -0.034 0 -0 0</pose>
				<geometry>
					<mesh>
						<scale>1 1 1</scale>
						<uri>model://youbot/meshes/youbot_arm/arm5.dae</uri>
					</mesh>
				</geometry>
				<material>
					<!--<script>
							<uri>__default__</uri>
							<name>__default__</name>
						</script>--></material>
			</visual>
			<visual name='arm_link_5_fixed_joint_lump__gripper_palm_link_visual_1'>
				<pose frame=''>0 0 0 0 -0 0</pose>
				<geometry>
					<mesh>
						<scale>1 1 1</scale>
						<uri>model://youbot/meshes/youbot_gripper/palm.dae</uri>
					</mesh>
				</geometry>
				<material>
					<script>
						<name>Gazebo/Black</name>
						<uri>model://youbot/materials/gazebo.material</uri>
					</script>
				</material>
			</visual>
			<velocity_decay/>
			<gravity>1</gravity>
			<velocity_decay/>
			<self_collide>1</self_collide>
			<kinematic>0</kinematic>
		</link>
		<joint name='arm_joint_5'
		       type='revolute'>
			<child>arm_link_5</child>
			<parent>arm_link_4</parent>
			<axis>
				<xyz>-0.360933 0.063642 -0.930418</xyz>
				<limit>
					<lower>0</lower>
					<upper>5.84685</upper>
					<effort>1</effort>
					<velocity>1.5708</velocity>
				</limit>
				<dynamics>
					<damping>1</damping>
					<friction>1</friction>
					<spring_reference>0</spring_reference>
					<spring_stiffness>0</spring_stiffness>
				</dynamics>
				<use_parent_model_frame>1</use_parent_model_frame>
			</axis>
		</joint>

		<link name="pen">
			<pose frame='arm_link_5'>0 0 0.1 0 0 0</pose>
			<inertial>
				<pose frame='arm_link_5'>0 0 0.05 0 0 0</pose>
				<mass>0.01</mass>
				<inertia>
					<ixx>0.01</ixx>
					<ixy>0</ixy>
					<ixz>0</ixz>
					<iyy>0.01</iyy>
					<iyz>0</iyz>
					<izz>0.01</izz>
				</inertia>
			</inertial>
			<collision name='pen_collision'>
				<pose frame='arm_link_5'>0 0 0.05 0 -0 0</pose>
				<geometry>
					<cylinder>
						<length>0.1</length>
						<radius>0.005</radius>
					</cylinder>
				</geometry>
				<max_contacts>10</max_contacts>
				<surface>
					<contact>
						<ode/>
					</contact>
					<bounce/>
					<friction>
						<torsional>
							<ode/>
						</torsional>
						<ode/>
					</friction>
				</surface>
			</collision>
			<visual name='pen_visual'>
				<pose frame='arm_link_5'>0 0 0.05 0 -0 0</pose>
				<geometry>
					<cylinder>
						<length>0.1</length>
						<radius>0.005</radius>
					</cylinder>
				</geometry>
			</visual>
			<self_collide>0</self_collide>
			<kinematic>0</kinematic>
			<gravity>1</gravity>
		</link>

		<joint name='pen_joint'
		       type='fixed'>
			<child>pen</child>
			<parent>arm_link_5</parent>
			<axis>
				<xyz>0 0 0</xyz>
				<dynamics>
					<damping>1</damping>
					<friction>1</friction>
					<spring_reference>0</spring_reference>
					<spring_stiffness>0</spring_stiffness>
				</dynamics>
				<use_parent_model_frame>1</use_parent_model_frame>
			</axis>
		</joint>

		<link name='caster_link_bl'>
			<pose frame=''>-0.228 0.158 -0.034 0 -0 0</pose>
			<inertial>
				<pose frame=''>0 0 0 0 -0 0</pose>
				<mass>0.1</mass>
				<inertia>
					<ixx>0.0124118</ixx>
					<ixy>-0.000711734</ixy>
					<ixz>0.00050273</ixz>
					<iyy>0.0152182</iyy>
					<iyz>-4.27347e-06</iyz>
					<izz>0.011764</izz>
				</inertia>
			</inertial>
			<gravity>1</gravity>
			<velocity_decay/>
			<self_collide>0</self_collide>
			<kinematic>0</kinematic>
		</link>
		<joint name='caster_joint_bl'
		       type='revolute'>
			<child>caster_link_bl</child>
			<parent>base_footprint</parent>
			<axis>
				<xyz>0 0 1</xyz>
				<limit>
					<lower>-1e+16</lower>
					<upper>1e+16</upper>
				</limit>
				<dynamics>
					<damping>1</damping>
					<friction>1</friction>
					<spring_reference>0</spring_reference>
					<spring_stiffness>0</spring_stiffness>
				</dynamics>
				<use_parent_model_frame>1</use_parent_model_frame>
			</axis>
		</joint>
		<link name='wheel_link_bl'>
			<pose frame=''>-0.228 0.158 -0.034 0 -0 0</pose>
			<inertial>
				<pose frame=''>0 0 0 0 -0 0</pose>
				<mass>0.4</mass>
				<inertia>
					<ixx>0.0124118</ixx>
					<ixy>-0.000711734</ixy>
					<ixz>0.00050273</ixz>
					<iyy>0.0152182</iyy>
					<iyz>-4.27347e-06</iyz>
					<izz>0.011764</izz>
				</inertia>
			</inertial>
			<collision name='wheel_link_bl_collision'>
				<pose frame=''>0 0 0 1.5708 -0 0</pose>
				<geometry>
					<cylinder>
						<length>0.05</length>
						<radius>0.05</radius>
					</cylinder>
				</geometry>
				<surface>
					<contact>
						<ode>
							<kp>1e+06</kp>
							<kd>100</kd>
						</ode>
					</contact>
					<friction>
						<ode/>
						<torsional>
							<ode/>
						</torsional>
					</friction>
					<bounce/>
				</surface>
				<max_contacts>10</max_contacts>
			</collision>
			<visual name='wheel_link_bl_visual'>
				<pose frame=''>0 0 0 0 -0 0</pose>
				<geometry>
					<sphere>
						<radius>0.05</radius>
					</sphere>
				</geometry>
				<material>
					<script>
						<name>youbot/Orange</name>
						<uri>model://youbot/materials/gazebo.material</uri>
					</script>
				</material>
			</visual>
			<gravity>1</gravity>
			<velocity_decay/>
			<self_collide>0</self_collide>
			<kinematic>0</kinematic>
		</link>
		<joint name='wheel_joint_bl'
		       type='revolute'>
			<child>wheel_link_bl</child>
			<parent>caster_link_bl</parent>
			<axis>
				<xyz>0 1 0</xyz>
				<limit>
					<lower>-1e+16</lower>
					<upper>1e+16</upper>
				</limit>
				<dynamics>
					<damping>1</damping>
					<friction>1</friction>
					<spring_reference>0</spring_reference>
					<spring_stiffness>0</spring_stiffness>
				</dynamics>
				<use_parent_model_frame>1</use_parent_model_frame>
			</axis>
		</joint>
		<link name='caster_link_br'>
			<pose frame=''>-0.228 -0.158 -0.034 0 -0 0</pose>
			<inertial>
				<pose frame=''>0 0 0 0 -0 0</pose>
				<mass>0.1</mass>
				<inertia>
					<ixx>0.0124118</ixx>
					<ixy>-0.000711734</ixy>
					<ixz>0.00050273</ixz>
					<iyy>0.0152182</iyy>
					<iyz>-4.27347e-06</iyz>
					<izz>0.011764</izz>
				</inertia>
			</inertial>
			<gravity>1</gravity>
			<velocity_decay/>
			<self_collide>0</self_collide>
			<kinematic>0</kinematic>
		</link>
		<joint name='caster_joint_br'
		       type='revolute'>
			<child>caster_link_br</child>
			<parent>base_footprint</parent>
			<axis>
				<xyz>0 0 1</xyz>
				<limit>
					<lower>-1e+16</lower>
					<upper>1e+16</upper>
				</limit>
				<dynamics>
					<damping>1</damping>
					<friction>1</friction>
					<spring_reference>0</spring_reference>
					<spring_stiffness>0</spring_stiffness>
				</dynamics>
				<use_parent_model_frame>1</use_parent_model_frame>
			</axis>
		</joint>
		<link name='wheel_link_br'>
			<pose frame=''>-0.228 -0.158 -0.034 0 -0 0</pose>
			<inertial>
				<pose frame=''>0 0 0 0 -0 0</pose>
				<mass>0.4</mass>
				<inertia>
					<ixx>0.0124118</ixx>
					<ixy>-0.000711734</ixy>
					<ixz>0.00050273</ixz>
					<iyy>0.0152182</iyy>
					<iyz>-4.27347e-06</iyz>
					<izz>0.011764</izz>
				</inertia>
			</inertial>
			<collision name='wheel_link_br_collision'>
				<pose frame=''>0 0 0 1.5708 -0 0</pose>
				<geometry>
					<cylinder>
						<length>0.05</length>
						<radius>0.05</radius>
					</cylinder>
				</geometry>
				<surface>
					<contact>
						<ode>
							<kp>1e+06</kp>
							<kd>100</kd>
						</ode>
					</contact>
					<friction>
						<ode/>
						<torsional>
							<ode/>
						</torsional>
					</friction>
					<bounce/>
				</surface>
				<max_contacts>10</max_contacts>
			</collision>
			<visual name='wheel_link_br_visual'>
				<pose frame=''>0 0 0 0 -0 0</pose>
				<geometry>
					<sphere>
						<radius>0.05</radius>
					</sphere>
				</geometry>
				<material>
					<script>
						<name>youbot/Orange</name>
						<uri>model://youbot/materials/gazebo.material</uri>
					</script>
				</material>
			</visual>
			<gravity>1</gravity>
			<velocity_decay/>
			<self_collide>0</self_collide>
			<kinematic>0</kinematic>
		</link>
		<joint name='wheel_joint_br'
		       type='revolute'>
			<child>wheel_link_br</child>
			<parent>caster_link_br</parent>
			<axis>
				<xyz>0 1 0</xyz>
				<limit>
					<lower>-1e+16</lower>
					<upper>1e+16</upper>
				</limit>
				<dynamics>
					<damping>1</damping>
					<friction>1</friction>
					<spring_reference>0</spring_reference>
					<spring_stiffness>0</spring_stiffness>
				</dynamics>
				<use_parent_model_frame>1</use_parent_model_frame>
			</axis>
		</joint>
		<link name='caster_link_fl'>
			<pose frame=''>0.228 0.158 -0.034 0 -0 0</pose>
			<inertial>
				<pose frame=''>0 0 0 0 -0 0</pose>
				<mass>0.1</mass>
				<inertia>
					<ixx>0.0124118</ixx>
					<ixy>-0.000711734</ixy>
					<ixz>0.00050273</ixz>
					<iyy>0.0152182</iyy>
					<iyz>-4.27347e-06</iyz>
					<izz>0.011764</izz>
				</inertia>
			</inertial>
			<gravity>1</gravity>
			<velocity_decay/>
			<self_collide>0</self_collide>
			<kinematic>0</kinematic>
		</link>
		<joint name='caster_joint_fl'
		       type='revolute'>
			<child>caster_link_fl</child>
			<parent>base_footprint</parent>
			<axis>
				<xyz>0 0 1</xyz>
				<limit>
					<lower>-1e+16</lower>
					<upper>1e+16</upper>
				</limit>
				<dynamics>
					<damping>1</damping>
					<friction>1</friction>
					<spring_reference>0</spring_reference>
					<spring_stiffness>0</spring_stiffness>
				</dynamics>
				<use_parent_model_frame>1</use_parent_model_frame>
			</axis>
		</joint>
		<link name='wheel_link_fl'>
			<pose frame=''>0.228 0.158 -0.034 0 -0 0</pose>
			<inertial>
				<pose frame=''>0 0 0 0 -0 0</pose>
				<mass>0.4</mass>
				<inertia>
					<ixx>0.0124118</ixx>
					<ixy>-0.000711734</ixy>
					<ixz>0.00050273</ixz>
					<iyy>0.0152182</iyy>
					<iyz>-4.27347e-06</iyz>
					<izz>0.011764</izz>
				</inertia>
			</inertial>
			<collision name='wheel_link_fl_collision'>
				<pose frame=''>0 0 0 1.5708 -0 0</pose>
				<geometry>
					<cylinder>
						<length>0.05</length>
						<radius>0.05</radius>
					</cylinder>
				</geometry>
				<surface>
					<contact>
						<ode>
							<kp>1e+06</kp>
							<kd>100</kd>
						</ode>
					</contact>
					<friction>
						<ode/>
						<torsional>
							<ode/>
						</torsional>
					</friction>
					<bounce/>
				</surface>
				<max_contacts>10</max_contacts>
			</collision>
			<visual name='wheel_link_fl_visual'>
				<pose frame=''>0 0 0 0 -0 0</pose>
				<geometry>
					<sphere>
						<radius>0.05</radius>
					</sphere>
				</geometry>
				<material>
					<script>
						<name>youbot/Orange</name>
						<uri>model://youbot/materials/gazebo.material</uri>
					</script>
				</material>
			</visual>
			<gravity>1</gravity>
			<velocity_decay/>
			<self_collide>0</self_collide>
			<kinematic>0</kinematic>
		</link>
		<joint name='wheel_joint_fl'
		       type='revolute'>
			<child>wheel_link_fl</child>
			<parent>caster_link_fl</parent>
			<axis>
				<xyz>0 1 0</xyz>
				<limit>
					<lower>-1e+16</lower>
					<upper>1e+16</upper>
				</limit>
				<dynamics>
					<damping>1</damping>
					<friction>1</friction>
					<spring_reference>0</spring_reference>
					<spring_stiffness>0</spring_stiffness>
				</dynamics>
				<use_parent_model_frame>1</use_parent_model_frame>
			</axis>
		</joint>
		<link name='caster_link_fr'>
			<pose frame=''>0.228 -0.158 -0.034 0 -0 0</pose>
			<inertial>
				<pose frame=''>0 0 0 0 -0 0</pose>
				<mass>0.1</mass>
				<inertia>
					<ixx>0.0124118</ixx>
					<ixy>-0.000711734</ixy>
					<ixz>0.00050273</ixz>
					<iyy>0.0152182</iyy>
					<iyz>-4.27347e-06</iyz>
					<izz>0.011764</izz>
				</inertia>
			</inertial>
			<gravity>1</gravity>
			<velocity_decay/>
			<self_collide>0</self_collide>
			<kinematic>0</kinematic>
		</link>
		<joint name='caster_joint_fr'
		       type='revolute'>
			<child>caster_link_fr</child>
			<parent>base_footprint</parent>
			<axis>
				<xyz>0 0 1</xyz>
				<limit>
					<lower>-1e+16</lower>
					<upper>1e+16</upper>
				</limit>
				<dynamics>
					<damping>1</damping>
					<friction>1</friction>
					<spring_reference>0</spring_reference>
					<spring_stiffness>0</spring_stiffness>
				</dynamics>
				<use_parent_model_frame>1</use_parent_model_frame>
			</axis>
		</joint>
		<link name='wheel_link_fr'>
			<pose frame=''>0.228 -0.158 -0.034 0 -0 0</pose>
			<inertial>
				<pose frame=''>0 0 0 0 -0 0</pose>
				<mass>0.4</mass>
				<inertia>
					<ixx>0.0124118</ixx>
					<ixy>-0.000711734</ixy>
					<ixz>0.00050273</ixz>
					<iyy>0.0152182</iyy>
					<iyz>-4.27347e-06</iyz>
					<izz>0.011764</izz>
				</inertia>
			</inertial>
			<collision name='wheel_link_fr_collision'>
				<pose frame=''>0 0 0 1.5708 -0 0</pose>
				<geometry>
					<cylinder>
						<length>0.05</length>
						<radius>0.05</radius>
					</cylinder>
				</geometry>
				<surface>
					<contact>
						<ode>
							<kp>1e+06</kp>
							<kd>100</kd>
						</ode>
					</contact>
					<friction>
						<ode/>
						<torsional>
							<ode/>
						</torsional>
					</friction>
					<bounce/>
				</surface>
				<max_contacts>10</max_contacts>
			</collision>
			<visual name='wheel_link_fr_visual'>
				<pose frame=''>0 0 0 0 -0 0</pose>
				<geometry>
					<sphere>
						<radius>0.05</radius>
					</sphere>
				</geometry>
				<material>
					<script>
						<name>youbot/Orange</name>
						<uri>model://youbot/materials/gazebo.material</uri>
					</script>
				</material>
			</visual>
			<gravity>1</gravity>
			<velocity_decay/>
			<self_collide>0</self_collide>
			<kinematic>0</kinematic>
		</link>
		<joint name='wheel_joint_fr'
		       type='revolute'>
			<child>wheel_link_fr</child>
			<parent>caster_link_fr</parent>
			<axis>
				<xyz>0 1 0</xyz>
				<limit>
					<lower>-1e+16</lower>
					<upper>1e+16</upper>
				</limit>
				<dynamics>
					<damping>1</damping>
					<friction>1</friction>
					<spring_reference>0</spring_reference>
					<spring_stiffness>0</spring_stiffness>
				</dynamics>
				<use_parent_model_frame>1</use_parent_model_frame>
			</axis>
		</joint>
		<!-- <plugin name='gazebo_ros2_control'
		        filename='libgazebo_ros2_control.so'>
			<robotNamespace>/youbot</robotNamespace>
		</plugin> -->
		<static>0</static>
		<plugin name="gazebo_ros_joint_pose_trajectory" filename="libgazebo_ros_joint_pose_trajectory.so">
			<ros>
				<namespace>/youbot</namespace>
			</ros>
			<update_rate>100</update_rate>
		</plugin>

		<plugin name='base_controller'
		        filename='libgazebo_ros_planar_move.so'>
			<ros>	
				<namespace>/youbot</namespace>
				<!-- <argument>cmd_vel:=cmd_vel</argument>
				<argument>odom:=odom</argument> -->
			</ros>

			<!-- Set control loop update rate -->
			<update_rate>100</update_rate>
			<!-- Set odom publish rate -->
			<publish_rate>10</publish_rate>

			<!-- Set if odom required -->
			<publish_odom>true</publish_odom>
			<publish_odom_tf>true</publish_odom_tf>

			<!-- Frame IDs -->
			<robot_base_frame>base_footprint</robot_base_frame>

			<!-- Set odom covariance -->
			<covariance_x>0.0001</covariance_x>
			<covariance_y>0.0001</covariance_y>
			<covariance_yaw>0.01</covariance_yaw>
		</plugin>

		<plugin name="gazebo_ros_p3d" filename="libgazebo_ros_p3d.so">

			<ros>
				<!-- Add namespace and remap the default topic -->
				<namespace>/youbot</namespace>
				<argument>odom:=p3d</argument>
			</ros>

			<!-- Replace camelCase elements with camel_case ones -->
			<body_name>pen</body_name>
			<frame_name>ground_plane</frame_name>
			<update_rate>1</update_rate>
			<!-- <xyz_offset>1 1 1</xyz_offset>
			<rpy_offset>0.1 0.1 0.1</rpy_offset> -->
			<gaussian_noise>0.01</gaussian_noise>

      	</plugin>

		<pose frame=''>0 0 0 0 -0 0</pose>
	</model>
</sdf>
